Workbook

Sheet Annahmen
B2: Wirtschaftlichkeitsrechnung Schlüsselverwaltung
B3: Gelb hinterlegte, blaue Zellen sind Eingaben. Alles andere rechnet sich selbst.
B5: 1 Personalkosten
B6: Bruttogehalt pro Monat | C6: 3000 | E6: Eingabe Nutzer
B7: Bruttogehalt pro Jahr | C7: =C6*12 -> 36000
B8: Arbeitgeberanteil SV, Umlagen, Berufsgenossenschaft | C8: 0.22 | E8: Erfahrungswert; je nach Umlagesätzen 20–23 %
B9: Arbeitsplatzkosten pro Jahr (IT, Fläche, Ausstattung) | C9: 6000 | E9: Annahme; bitte an eigene Werte anpassen
B10: Jahresvollkosten je Mitarbeiter | C10: =C7*(1+C8)+C9 -> 49920
B12: 2 Produktive Stunden pro Jahr
B13: Wochenstunden | C13: 40 | D13: h
B14: Bruttostunden (52 Wochen) | C14: =C13*52 -> 2080 | D14: h
B15: Urlaubstage | C15: 30 | D15: Tage
B16: Feiertage | C16: 10 | D16: Tage
B17: Krankheitstage | C17: 10 | D17: Tage
B18: Fortbildungsstunden | C18: 24 | D18: h
B19: Anwesenheitsstunden | C19: =C14-(C15+C16+C17)*C13/5-C18 -> 1656 | D19: h
B20: Unproduktiver Anteil | C20: 0.15 | E20: Pausen, Rüstzeiten, interne Abstimmung
B21: Produktive Stunden | C21: =C19*(1-C20) -> 1407.6 | D21: h
B22: Vollkostensatz pro produktiver Stunde | C22: =C10/C21 -> 35.464621 | E22: Vergleich naiv (Brutto / 2.080 h): siehe Zelle C23. Der Unterschied ist der häufigste Rechenfehler.
B23: zum Vergleich: naiver Stundenlohn (Brutto / 2.080 h) | C23: =C7/2080 -> 17.307692
B25: 3 Mengengerüst
B26: Arbeitstage pro Jahr | C26: 250 | D26: Tage
B27: Schlüsselbewegungen pro Arbeitstag | C27: 5 | D27: Stk | E27: Ausgabe und Rücknahme zählen je als eine Bewegung
B28: Ausleihvorgänge pro Jahr | C28: =C26*C27/2 -> 625 | D28: Stk | E28: Ein Vorgang = eine Ausgabe + eine Rücknahme
B29: Zwischenanfragen pro Woche ("ist der Schlüssel da?") | C29: 5 | D29: Stk | E29: Eingabe Nutzer
B30: Zwischenanfragen pro Jahr | C30: =C29*C26/5 -> 250 | D30: Stk
B31: Anteil Schlüssel, die am Haken hängen | C31: 0.8 | E31: Annahme; bestimmt, wie oft das Schlüsselbuch durchsucht werden musste
B33: 4 Zeiten je Ereignis (Minuten) | C33: vorher | D33: nachher
B34: 1 Haken prüfen, Schlüssel ist da | C34: 5 | D34: 1.5 | E34: Ereignis 1: Anfrage kommt herein, Verfügbarkeit muss geklärt werden.
B35: 1b Schlüssel fehlt: Schlüsselbuch durchsuchen | C35: 20 | D35: 1.5 | E35: Bis zu 30 Min. laut Nutzer; hier konservativ 20
B36: 2 Ausgabe dokumentieren und aushändigen | C36: 5 | D36: 1 | E36: Person, Firma, Kontakt leserlich erfassen
B37: 3 Rücknahme: Eintrag finden, quittieren, zurückhängen | C37: 7 | D37: 0.5
B38: 4 Zwischenanfrage beantworten | C38: 20 | D38: 1 | E38: Bis zu 30 Min. laut Nutzer; hier konservativ 20
B40: 5 Kosten der Lösung
B41: Lizenz pro Monat (netto) | C41: 99 | E41: easyDing, eine Lizenz je Standort
B42: Lizenz pro Jahr | C42: =C41*12 -> 1188
B43: Administrationsaufwand pro Jahr | C43: 4 | D43: h
B44: Hardware einmalig (Tablet mit Kamera, optional) | C44: 250 | E44: Nicht zwingend – ein vorhandener PC genügt
B45: Schlüssel im Bestand | C45: 12000 | D45: Stk
B46: Erfassungsdauer je Schlüssel | C46: 0.5 | D46: Min | E46: Alternativszenario 1,0 Min. siehe Blatt Szenarien
...

Sheet Rechnung
B2: Ergebnis
B3: Alle Werte rechnen sich aus dem Blatt Annahmen.
B5: 1 Zeitersparnis pro Jahr
C6: Fälle/Jahr | D6: vorher Min | E6: nachher Min | F6: Stunden | G6: Wert
B7: Verfügbarkeit klären (Haken bzw. Buch) | C7: =Annahmen!C28 -> 625 | D7: =Annahmen!C31*Annahmen!C34+(1-Annahmen!C31)*Annahmen!C35 -> 8 | E7: =Annahmen!D34 -> 1.5 | F7: =C7*(D7-E7)/60 -> 67.708333 | G7: =F7*Annahmen!$C$22 -> 2401.2504
B8: Ausgabe dokumentieren | C8: =Annahmen!C28 -> 625 | D8: =Annahmen!C36 -> 5 | E8: =Annahmen!D36 -> 1 | F8: =C8*(D8-E8)/60 -> 41.666667 | G8: =F8*Annahmen!$C$22 -> 1477.6925
B9: Rücknahme dokumentieren | C9: =Annahmen!C28 -> 625 | D9: =Annahmen!C37 -> 7 | E9: =Annahmen!D37 -> 0.5 | F9: =C9*(D9-E9)/60 -> 67.708333 | G9: =F9*Annahmen!$C$22 -> 2401.2504
B10: Zwischenanfragen beantworten | C10: =Annahmen!C30 -> 250 | D10: =Annahmen!C38 -> 20 | E10: =Annahmen!D38 -> 1 | F10: =C10*(D10-E10)/60 -> 79.166667 | G10: =F10*Annahmen!$C$22 -> 2807.6158
B11: Summe | F11: =SUM(F7:F10) -> 256.25 | G11: =SUM(G7:G10) -> 9087.809 | H11: Ereignis 1 und 4 zusammen machen den größten Anteil aus – siehe Zelle H12.
B12: davon Anteil "wo ist der Schlüssel?" (Ereignis 1 + 4) | G12: =(F7+F10)/F11 -> 0.57317073
B13: Vollzeitäquivalente | G13: =F11/Annahmen!C21 -> 0.18204746
B15: 2 Risikoreduktion pro Jahr
B16: Belastung je Fall ohne Nachweis | G16: =Annahmen!C53*(1-Annahmen!C54)+Annahmen!C56 -> 8025 | H16: Ankerwerte aus OLG Brandenburg, Urteil vom 27.04.2023, Az. 10 U 100/22.
B17: Belastung je Fall mit Nachweis | G17: =Annahmen!C53*(1-Annahmen!C55)+Annahmen!C57 -> 2760 | H17: Die Quote "mit Nachweis" ist eine Annahme, kein Gerichtswert.
B18: Differenz je Fall | G18: =G16-G17 -> 5265
B19: Risikoreduktion pro Jahr | G19: =G18/Annahmen!C58 -> 1755
B21: 3 Kosten
B22: Lizenz pro Jahr | G22: =Annahmen!C42 -> 1188
B23: Administration pro Jahr | G23: =Annahmen!C43*Annahmen!C22 -> 141.85848
B24: Laufende Kosten pro Jahr | G24: =SUM(G22:G23) -> 1329.8585
B26: Ersterfassung (Schlüssel × Dauer) | G26: =Annahmen!C45*Annahmen!C46/60*Annahmen!C22 -> 3546.4621
B27: Hardware | G27: =Annahmen!C44 -> 250
B28: Schulung | G28: =Annahmen!C47*Annahmen!C48*Annahmen!C22 -> 425.57545
B29: Konfiguration und Projektleitung | G29: =Annahmen!C49*Annahmen!C22 -> 709.29241
B30: Produktivitätsdelle | G30: =Annahmen!C50*Annahmen!C22 -> 886.61552
B31: Einmalkosten gesamt | G31: =SUM(G26:G30) -> 5817.9454
B33: 4 Ergebnis
B34: Zeitwert pro Jahr | G34: =G11 -> 9087.809
B35: Risikoreduktion pro Jahr | G35: =G19 -> 1755
B36: abzüglich laufende Kosten | G36: =-G24 -> -1329.8585
B37: Jahresnutzen | G37: =G34+G35+G36 -> 9512.9506
B39: Amortisation der Einmalkosten | G39: =IF(G37<=0,"n/a",G31/G37*12) -> 7.3389791
B40: Kosten je gewonnener Arbeitsstunde | G40: =IF(F11<=0,"n/a",G24/F11) -> 5.1896916 | H40: Dagegen: Vollkostensatz auf Blatt Annahmen, Zelle C22.
B41: Break-even: Zwischenanfragen pro Woche | G41: =G24/Annahmen!C22*60/(Annahmen!C38-Annahmen!D38)/(Annahmen!C26/5) -> 2.3683057 | H41: Ab so vielen Suchvorgängen pro Woche tragen sich die laufenden Kosten allein daraus.

Sheet Szenarien
B2: Szenarien
B3: Die Spalten sortieren danach, wie günstig die Rechnung ausfällt – nicht danach, wie pessimistisch die einzelne Annahme klingt. Alle vier Hebel zeigen in dieselbe Richtung: links wird der Nutzen kleingerechnet und die Kosten hochgesetzt, rechts umgekehrt.
B5: Stellhebel | C5: vorsichtig | D5: realistisch | E5: günstig
B6: Anteil Schlüssel am Haken (hoch = weniger Sucherei vorher) | C6: 0.8 | D6: 0.7 | E6: 0.6
B7: Suchdauer im Schlüsselbuch (Min) (kurz = weniger Ersparnis) | C7: 20 | D7: 25 | E7: 30
B8: Erfassungsdauer je Schlüssel (Min) (lang = höhere Einmalkosten) | C8: 1 | D8: 0.75 | E8: 0.5
B9: Schadensfall alle ... Jahre (selten = weniger Risikonutzen) | C9: 4 | D9: 3 | E9: 2
B11: Ergebnis
B12: Gesparte Stunden pro Jahr | C12: =Annahmen!$C$28*((C6*Annahmen!$C$34+(1-C6)*C7)-Annahmen!$D$34)/60+Annahmen!$C$28*(Annahmen!$C$36-Annahmen!$D$36)/60+Annahmen!$C$28*(Annahmen!$C$37-Annahmen!$D$37)/60+Annahmen!$C$30*(C7-Annahmen!$D$38)/60 -> 256.25 | D12: =Annahmen!$C$28*((D6*Annahmen!$C$34+(1-D6)*D7)-Annahmen!$D$34)/60+Annahmen!$C$28*(Annahmen!$C$36-Annahmen!$D$36)/60+Annahmen!$C$28*(Annahmen!$C$37-Annahmen!$D$37)/60+Annahmen!$C$30*(D7-Annahmen!$D$38)/60 -> 308.33333 | E12: =Annahmen!$C$28*((E6*Annahmen!$C$34+(1-E6)*E7)-Annahmen!$D$34)/60+Annahmen!$C$28*(Annahmen!$C$36-Annahmen!$D$36)/60+Annahmen!$C$28*(Annahmen!$C$37-Annahmen!$D$37)/60+Annahmen!$C$30*(E7-Annahmen!$D$38)/60 -> 370.83333
B13: Zeitwert pro Jahr | C13: =C12*Annahmen!$C$22 -> 9087.809 | D13: =D12*Annahmen!$C$22 -> 10934.925 | E13: =E12*Annahmen!$C$22 -> 13151.463 | F13: Bewertet mit dem Vollkostensatz aus Blatt Annahmen, Zelle C22.
B14: Risikoreduktion pro Jahr | C14: =(Annahmen!$C$53*(1-Annahmen!$C$54)+Annahmen!$C$56-(Annahmen!$C$53*(1-Annahmen!$C$55)+Annahmen!$C$57))/C9 -> 1316.25 | D14: =(Annahmen!$C$53*(1-Annahmen!$C$54)+Annahmen!$C$56-(Annahmen!$C$53*(1-Annahmen!$C$55)+Annahmen!$C$57))/D9 -> 1755 | E14: =(Annahmen!$C$53*(1-Annahmen!$C$54)+Annahmen!$C$56-(Annahmen!$C$53*(1-Annahmen!$C$55)+Annahmen!$C$57))/E9 -> 2632.5
B15: Jahresnutzen | C15: =C13+C14-Rechnung!$G$24 -> 9074.2006 | D15: =D13+D14-Rechnung!$G$24 -> 11360.066 | E15: =E13+E14-Rechnung!$G$24 -> 14454.105 | F15: Jahresnutzen = Zeitwert + Risikoreduktion − laufende Kosten.
B16: Einmalkosten | C16: =Annahmen!$C$45*C8/60*Annahmen!$C$22+Annahmen!$C$44+Annahmen!$C$47*Annahmen!$C$48*Annahmen!$C$22+Annahmen!$C$49*Annahmen!$C$22+Annahmen!$C$50*Annahmen!$C$22 -> 9364.4075 | D16: =Annahmen!$C$45*D8/60*Annahmen!$C$22+Annahmen!$C$44+Annahmen!$C$47*Annahmen!$C$48*Annahmen!$C$22+Annahmen!$C$49*Annahmen!$C$22+Annahmen!$C$50*Annahmen!$C$22 -> 7591.1765 | E16: =Annahmen!$C$45*E8/60*Annahmen!$C$22+Annahmen!$C$44+Annahmen!$C$47*Annahmen!$C$48*Annahmen!$C$22+Annahmen!$C$49*Annahmen!$C$22+Annahmen!$C$50*Annahmen!$C$22 -> 5817.9454
B17: Amortisation | C17: =IF(C15<=0,"n/a",C16/C15*12) -> 12.383779 | D17: =IF(D15<=0,"n/a",D16/D15*12) -> 8.0188016 | E17: =IF(E15<=0,"n/a",E16/E15*12) -> 4.8301396
